<?xml version="1.0" ?>
<!-- =================================================================================== -->
<!-- |    This document was autogenerated by xacro from mh5_robot_revH.urdf.xacro      | -->
<!-- |    EDITING THIS FILE BY HAND IS NOT RECOMMENDED                                 | -->
<!-- =================================================================================== -->
<robot name="mh5_robot">
  <mujoco>
    <compiler meshdir="meshes/" balanceinertia="true" discardvisual="false"/>
  </mujoco>
  <link name="base_link"/>
  <link name="chest">
    <visual>
      <origin rpy="0 0 0" xyz="0 0 0"/>
      <geometry>
        <mesh filename="package://mh5_description/meshes/chest_revH.stl"/>
      </geometry>
    </visual>
    <collision>
      <origin rpy="0 0 0" xyz="0 0 0"/>
      <geometry>
        <mesh filename="package://mh5_description/meshes/chest_revH.stl"/>
      </geometry>
    </collision>
    <inertial>
      <mass value="0.400"/>
      <inertia ixx="0.000954830" ixy="-0.000001668" ixz="-0.000021416" iyy="0.000597536" iyz="0.000000148" izz="0.000637274"/>
    </inertial>
  </link>
  <joint name="chest_fixed" type="floating">
    <parent link="base_link"/>
    <child link="chest"/>
    <origin rpy="0 0 0" xyz="0 0 0.203"/>
  </joint>
  <joint name="head_y" type="revolute">
    <axis xyz="0 0 1"/>
    <parent link="chest"/>
    <child link="head_servo"/>
    <origin rpy="0 0 0" xyz="-0.007076 0 0.19799999999999998"/>
    <limit effort="1.0" lower="-1.5707963267948966" upper="1.5707963267948966" velocity="6.283185307179586"/>
  </joint>
  <transmission name="head_y_tran">
    <type>transmission_interface/SimpleTransmission</type>
    <joint name="head_y">
      <hardwareInterface>hardware_interface/PositionJointInterface</hardwareInterface>
    </joint>
    <actuator name="head_y_motor">
      <!-- <hardwareInterface>hardware_interface/PositionJointInterface</hardwareInterface> -->
      <mechanicalReduction>1</mechanicalReduction>
    </actuator>
  </transmission>
  <link name="head_servo">
    <visual>
      <origin rpy="0 1.5707963267948966 3.141592653589793" xyz="0 0 0"/>
      <geometry>
        <mesh filename="package://mh5_description/meshes/2XL430_1_idle_revC.stl"/>
      </geometry>
      <material name="black">
        <color rgba="0.2 0.2 0.2 1"/>
      </material>
    </visual>
    <collision>
      <origin rpy="0 0 0" xyz="0 0 0"/>
      <geometry>
        <mesh filename="package://mh5_description/meshes/2XL430_1_idle_revC.stl"/>
      </geometry>
    </collision>
    <inertial>
      <mass value="0.098"/>
      <inertia ixx="0.000026983" ixy="0.000000654" ixz="-0.000000001" iyy="0.000026983" iyz="0.000000002" izz="0.000019139"/>
    </inertial>
  </link>
  <joint name="head_p" type="revolute">
    <axis xyz="0 -1 0"/>
    <parent link="head_servo"/>
    <child link="head_frame"/>
    <origin rpy="0 0 0" xyz="0.024 0 0"/>
    <limit effort="1.0" lower="-0.3490658503988659" upper="0.7853981633974483" velocity="6.283185307179586"/>
  </joint>
  <transmission name="head_p_tran">
    <type>transmission_interface/SimpleTransmission</type>
    <joint name="head_p">
      <hardwareInterface>hardware_interface/PositionJointInterface</hardwareInterface>
    </joint>
    <actuator name="head_p_motor">
      <!-- <hardwareInterface>hardware_interface/PositionJointInterface</hardwareInterface> -->
      <mechanicalReduction>1</mechanicalReduction>
    </actuator>
  </transmission>
  <link name="head_frame">
    <visual>
      <origin rpy="0 0 0" xyz="0 0 0"/>
      <geometry>
        <mesh filename="package://mh5_description/meshes/head_revH.stl"/>
      </geometry>
      <material name="ivory">
        <color rgba="0.8 0.8 0.8 1"/>
      </material>
    </visual>
    <collision>
      <origin rpy="0 0 0" xyz="0 0 0"/>
      <geometry>
        <mesh filename="package://mh5_description/meshes/head_revH.stl"/>
      </geometry>
    </collision>
    <inertial>
      <mass value="0.090046"/>
      <inertia ixx="0.000188152" ixy="0.000000008" ixz="-0.000000404" iyy="0.000158702" iyz="-0.000000005" izz="0.000215838"/>
    </inertial>
  </link>
  <joint name="left_camera_fixed" type="fixed">
    <parent link="head_frame"/>
    <child link="left_camera"/>
    <origin rpy="0 0 0" xyz="0.029469 0.025 -0.008281"/>
  </joint>
  <link name="left_camera"/>
  <joint name="right_camera_fixed" type="fixed">
    <parent link="head_frame"/>
    <child link="right_camera"/>
    <origin rpy="0 0 0" xyz="0.029469 -0.025 -0.008281"/>
  </joint>
  <link name="right_camera"/>
  <joint name="l_sho_p" type="revolute">
    <axis xyz="0 0 1.0"/>
    <parent link="chest"/>
    <child link="left_shoulder_frame"/>
    <origin rpy="1.5707963267948966 -1.5707963267948966 0 " xyz="0 0.0685 0.11875"/>
    <!-- <origin xyz="0 0 0.019" rpy="0 ${pi} ${pi/2 - factor*pi/2}"/> -->
    <limit effort="1.0" lower="-1.5707963267948966" upper="3.141592653589793" velocity="6.283185307179586"/>
  </joint>
  <transmission name="l_sho_p_tran">
    <type>transmission_interface/SimpleTransmission</type>
    <joint name="l_sho_p">
      <hardwareInterface>hardware_interface/PositionJointInterface</hardwareInterface>
    </joint>
    <actuator name="l_sho_p_motor">
      <!-- <hardwareInterface>hardware_interface/PositionJointInterface</hardwareInterface> -->
      <mechanicalReduction>1</mechanicalReduction>
    </actuator>
  </transmission>
  <link name="left_shoulder_frame">
    <visual>
      <origin rpy="0 0 0" xyz="0 0 0"/>
      <geometry>
        <mesh filename="package://mh5_description/meshes/frame04_revE.stl"/>
      </geometry>
      <material name="ivory"/>
    </visual>
    <collision>
      <origin rpy="0 0 0" xyz="0 0 0"/>
      <geometry>
        <mesh filename="package://mh5_description/meshes/frame04_revE.stl"/>
      </geometry>
    </collision>
    <inertial>
      <mass value="0.0083"/>
      <inertia ixx="0.000003285" ixy="0.000000000" ixz="-0.000000402" iyy="0.000001666" iyz="0.000000000" izz="0.000003578"/>
    </inertial>
  </link>
  <joint name="l_sho_r" type="revolute">
    <axis xyz="1.0 0 0"/>
    <parent link="left_shoulder_frame"/>
    <child link="left_upper_arm"/>
    <origin rpy="-1.5707963267948966 0 -1.5707963267948966" xyz="-0.008 0 -0.027"/>
    <!-- <origin xyz="0 ${-factor*0.016} -0.027" rpy="0 ${pi/2} ${pi/2 - factor*pi/2}"/> -->
    <limit effort="1.0" lower="0" upper="3.141592653589793" velocity="6.283185307179586"/>
  </joint>
  <transmission name="l_sho_r_tran">
    <type>transmission_interface/SimpleTransmission</type>
    <joint name="l_sho_r">
      <hardwareInterface>hardware_interface/PositionJointInterface</hardwareInterface>
    </joint>
    <actuator name="l_sho_r_motor">
      <!-- <hardwareInterface>hardware_interface/PositionJointInterface</hardwareInterface> -->
      <mechanicalReduction>1</mechanicalReduction>
    </actuator>
  </transmission>
  <link name="left_upper_arm">
    <visual>
      <origin rpy="0 0 0" xyz="0 0 0"/>
      <geometry>
        <mesh filename="package://mh5_description/meshes/upper_arm.stl"/>
      </geometry>
      <material name="black"/>
    </visual>
    <collision>
      <origin rpy="0 0 0" xyz="0 0 0"/>
      <geometry>
        <mesh filename="package://mh5_description/meshes/upper_arm.stl"/>
      </geometry>
    </collision>
    <inertial>
      <mass value="0.115"/>
      <inertia ixx="0.000089448" ixy="0.000000000" ixz="0.000000000" iyy="0.000092555" iyz="0.000000036" izz="0.000017800"/>
    </inertial>
  </link>
  <joint name="l_elb_r" type="revolute">
    <axis xyz="0 0 1.0"/>
    <parent link="left_upper_arm"/>
    <child link="left_elbow_frame"/>
    <origin rpy="0 -1.5707963267948966 0" xyz="0.019 0 -0.0705"/>
    <limit effort="1.0" lower="-1.5707963267948966" upper="1.5707963267948966" velocity="6.283185307179586"/>
  </joint>
  <transmission name="l_elb_y_tran">
    <type>transmission_interface/SimpleTransmission</type>
    <joint name="l_elb_y">
      <hardwareInterface>hardware_interface/PositionJointInterface</hardwareInterface>
    </joint>
    <actuator name="l_elb_y_motor">
      <!-- <hardwareInterface>hardware_interface/PositionJointInterface</hardwareInterface> -->
      <mechanicalReduction>1</mechanicalReduction>
    </actuator>
  </transmission>
  <link name="left_elbow_frame">
    <visual>
      <origin rpy="0 0 0" xyz="0 0 0"/>
      <geometry>
        <mesh filename="package://mh5_description/meshes/frame02_revC.stl"/>
      </geometry>
      <material name="ivory">
        <color rgba="0.8 0.8 0.8 1"/>
      </material>
    </visual>
    <collision>
      <origin rpy="0 0 0" xyz="0 0 0"/>
      <geometry>
        <mesh filename="package://mh5_description/meshes/frame02_revC.stl"/>
      </geometry>
    </collision>
    <inertial>
      <origin rpy="0 0 0" xyz="0 0 0"/>
      <mass value="0.0077"/>
      <inertia ixx="0.000003217" ixy="0.000000000" ixz="-0.000000011" iyy="0.000001377" iyz="0.000000000" izz="0.000002781"/>
    </inertial>
  </link>
  <joint name="l_elb_p" type="revolute">
    <axis xyz="0 -1 0"/>
    <parent link="left_elbow_frame"/>
    <child link="left_lower_arm"/>
    <origin rpy="0 1.5707963267948966 0" xyz="0 0 -0.034"/>
    <limit effort="1.0" lower="-1.8849555921538759" upper="1.8849555921538759" velocity="6.283185307179586"/>
  </joint>
  <transmission name="l_elb_p_tran">
    <type>transmission_interface/SimpleTransmission</type>
    <joint name="l_elb_p">
      <hardwareInterface>hardware_interface/PositionJointInterface</hardwareInterface>
    </joint>
    <actuator name="l_elb_p_motor">
      <!-- <hardwareInterface>hardware_interface/PositionJointInterface</hardwareInterface> -->
      <mechanicalReduction>1</mechanicalReduction>
    </actuator>
  </transmission>
  <link name="left_lower_arm">
    <visual>
      <origin rpy="0 0 0" xyz="0 0 0"/>
      <geometry>
        <mesh filename="package://mh5_description/meshes/left_lower_arm.stl"/>
      </geometry>
      <material name="black"/>
    </visual>
    <collision>
      <origin rpy="0 0 0" xyz="0 0 0"/>
      <geometry>
        <mesh filename="package://mh5_description/meshes/left_lower_arm.stl"/>
      </geometry>
    </collision>
    <inertial>
      <mass value="0.057"/>
      <inertia ixx="0.000013720" ixy="0.000000007" ixz="-0.000000355" iyy="0.000015234" iyz="0.000000006" izz="0.000008769"/>
    </inertial>
  </link>
  <joint name="l_gripper" type="revolute">
    <axis xyz="0 0 1.0"/>
    <parent link="left_lower_arm"/>
    <child link="left_gripper"/>
    <origin rpy="0 0 0" xyz="0.06575 0 0"/>
    <limit effort="1.0" lower="0" upper="1.5707963267948966" velocity="6.283185307179586"/>
  </joint>
  <transmission name="l_gripper_tran">
    <type>transmission_interface/SimpleTransmission</type>
    <joint name="l_gripper">
      <hardwareInterface>hardware_interface/PositionJointInterface</hardwareInterface>
    </joint>
    <actuator name="l_gripper_motor">
      <!-- <hardwareInterface>hardware_interface/PositionJointInterface</hardwareInterface> -->
      <mechanicalReduction>1</mechanicalReduction>
    </actuator>
  </transmission>
  <link name="left_gripper">
    <visual>
      <origin rpy="3.141592653589793 0 0" xyz="0 0 0"/>
      <geometry>
        <mesh filename="package://mh5_description/meshes/gripper.stl"/>
      </geometry>
      <material name="black"/>
    </visual>
    <collision>
      <origin rpy="0 0 0" xyz="0 0 0"/>
      <geometry>
        <mesh filename="package://mh5_description/meshes/gripper.stl"/>
      </geometry>
    </collision>
    <inertial>
      <mass value="0.004"/>
      <inertia ixx="0.000000750" ixy="0.000000067" ixz="0.000000000" iyy="0.000001252" iyz="0.000000000" izz="0.000000794"/>
    </inertial>
  </link>
  <joint name="r_sho_p" type="revolute">
    <axis xyz="0 0 -1.0"/>
    <parent link="chest"/>
    <child link="right_shoulder_frame"/>
    <origin rpy="-1.5707963267948966 -1.5707963267948966 0 " xyz="0 -0.0685 0.11875"/>
    <!-- <origin xyz="0 0 0.019" rpy="0 ${pi} ${pi/2 - factor*pi/2}"/> -->
    <limit effort="1.0" lower="-1.5707963267948966" upper="3.141592653589793" velocity="6.283185307179586"/>
  </joint>
  <transmission name="r_sho_p_tran">
    <type>transmission_interface/SimpleTransmission</type>
    <joint name="r_sho_p">
      <hardwareInterface>hardware_interface/PositionJointInterface</hardwareInterface>
    </joint>
    <actuator name="r_sho_p_motor">
      <!-- <hardwareInterface>hardware_interface/PositionJointInterface</hardwareInterface> -->
      <mechanicalReduction>1</mechanicalReduction>
    </actuator>
  </transmission>
  <link name="right_shoulder_frame">
    <visual>
      <origin rpy="0 0 0" xyz="0 0 0"/>
      <geometry>
        <mesh filename="package://mh5_description/meshes/frame04_revE.stl"/>
      </geometry>
      <material name="ivory"/>
    </visual>
    <collision>
      <origin rpy="0 0 0" xyz="0 0 0"/>
      <geometry>
        <mesh filename="package://mh5_description/meshes/frame04_revE.stl"/>
      </geometry>
    </collision>
    <inertial>
      <mass value="0.0083"/>
      <inertia ixx="0.000003285" ixy="0.000000000" ixz="-0.000000402" iyy="0.000001666" iyz="0.000000000" izz="0.000003578"/>
    </inertial>
  </link>
  <joint name="r_sho_r" type="revolute">
    <axis xyz="-1.0 0 0"/>
    <parent link="right_shoulder_frame"/>
    <child link="right_upper_arm"/>
    <origin rpy="1.5707963267948966 0 1.5707963267948966" xyz="-0.008 0 -0.027"/>
    <!-- <origin xyz="0 ${-factor*0.016} -0.027" rpy="0 ${pi/2} ${pi/2 - factor*pi/2}"/> -->
    <limit effort="1.0" lower="0" upper="3.141592653589793" velocity="6.283185307179586"/>
  </joint>
  <transmission name="r_sho_r_tran">
    <type>transmission_interface/SimpleTransmission</type>
    <joint name="r_sho_r">
      <hardwareInterface>hardware_interface/PositionJointInterface</hardwareInterface>
    </joint>
    <actuator name="r_sho_r_motor">
      <!-- <hardwareInterface>hardware_interface/PositionJointInterface</hardwareInterface> -->
      <mechanicalReduction>1</mechanicalReduction>
    </actuator>
  </transmission>
  <link name="right_upper_arm">
    <visual>
      <origin rpy="0 0 0" xyz="0 0 0"/>
      <geometry>
        <mesh filename="package://mh5_description/meshes/upper_arm.stl"/>
      </geometry>
      <material name="black"/>
    </visual>
    <collision>
      <origin rpy="0 0 0" xyz="0 0 0"/>
      <geometry>
        <mesh filename="package://mh5_description/meshes/upper_arm.stl"/>
      </geometry>
    </collision>
    <inertial>
      <mass value="0.115"/>
      <inertia ixx="0.000089448" ixy="0.000000000" ixz="0.000000000" iyy="0.000092555" iyz="0.000000036" izz="0.000017800"/>
    </inertial>
  </link>
  <joint name="r_elb_r" type="revolute">
    <axis xyz="0 0 -1.0"/>
    <parent link="right_upper_arm"/>
    <child link="right_elbow_frame"/>
    <origin rpy="0 -1.5707963267948966 0" xyz="0.019 0 -0.0705"/>
    <limit effort="1.0" lower="-1.5707963267948966" upper="1.5707963267948966" velocity="6.283185307179586"/>
  </joint>
  <transmission name="r_elb_y_tran">
    <type>transmission_interface/SimpleTransmission</type>
    <joint name="r_elb_y">
      <hardwareInterface>hardware_interface/PositionJointInterface</hardwareInterface>
    </joint>
    <actuator name="r_elb_y_motor">
      <!-- <hardwareInterface>hardware_interface/PositionJointInterface</hardwareInterface> -->
      <mechanicalReduction>1</mechanicalReduction>
    </actuator>
  </transmission>
  <link name="right_elbow_frame">
    <visual>
      <origin rpy="0 0 0" xyz="0 0 0"/>
      <geometry>
        <mesh filename="package://mh5_description/meshes/frame02_revC.stl"/>
      </geometry>
      <material name="ivory">
        <color rgba="0.8 0.8 0.8 1"/>
      </material>
    </visual>
    <collision>
      <origin rpy="0 0 0" xyz="0 0 0"/>
      <geometry>
        <mesh filename="package://mh5_description/meshes/frame02_revC.stl"/>
      </geometry>
    </collision>
    <inertial>
      <origin rpy="0 0 0" xyz="0 0 0"/>
      <mass value="0.0077"/>
      <inertia ixx="0.000003217" ixy="0.000000000" ixz="-0.000000011" iyy="0.000001377" iyz="0.000000000" izz="0.000002781"/>
    </inertial>
  </link>
  <joint name="r_elb_p" type="revolute">
    <axis xyz="0 -1 0"/>
    <parent link="right_elbow_frame"/>
    <child link="right_lower_arm"/>
    <origin rpy="0 1.5707963267948966 0" xyz="0 0 -0.034"/>
    <limit effort="1.0" lower="-1.8849555921538759" upper="1.8849555921538759" velocity="6.283185307179586"/>
  </joint>
  <transmission name="r_elb_p_tran">
    <type>transmission_interface/SimpleTransmission</type>
    <joint name="r_elb_p">
      <hardwareInterface>hardware_interface/PositionJointInterface</hardwareInterface>
    </joint>
    <actuator name="r_elb_p_motor">
      <!-- <hardwareInterface>hardware_interface/PositionJointInterface</hardwareInterface> -->
      <mechanicalReduction>1</mechanicalReduction>
    </actuator>
  </transmission>
  <link name="right_lower_arm">
    <visual>
      <origin rpy="0 0 0" xyz="0 0 0"/>
      <geometry>
        <mesh filename="package://mh5_description/meshes/right_lower_arm.stl"/>
      </geometry>
      <material name="black"/>
    </visual>
    <collision>
      <origin rpy="0 0 0" xyz="0 0 0"/>
      <geometry>
        <mesh filename="package://mh5_description/meshes/right_lower_arm.stl"/>
      </geometry>
    </collision>
    <inertial>
      <mass value="0.057"/>
      <inertia ixx="0.000013720" ixy="0.000000007" ixz="-0.000000355" iyy="0.000015234" iyz="0.000000006" izz="0.000008769"/>
    </inertial>
  </link>
  <joint name="r_gripper" type="revolute">
    <axis xyz="0 0 -1.0"/>
    <parent link="right_lower_arm"/>
    <child link="right_gripper"/>
    <origin rpy="0 0 0" xyz="0.06575 0 0"/>
    <limit effort="1.0" lower="0" upper="1.5707963267948966" velocity="6.283185307179586"/>
  </joint>
  <transmission name="r_gripper_tran">
    <type>transmission_interface/SimpleTransmission</type>
    <joint name="r_gripper">
      <hardwareInterface>hardware_interface/PositionJointInterface</hardwareInterface>
    </joint>
    <actuator name="r_gripper_motor">
      <!-- <hardwareInterface>hardware_interface/PositionJointInterface</hardwareInterface> -->
      <mechanicalReduction>1</mechanicalReduction>
    </actuator>
  </transmission>
  <link name="right_gripper">
    <visual>
      <origin rpy="0.0 0 0" xyz="0 0 0"/>
      <geometry>
        <mesh filename="package://mh5_description/meshes/gripper.stl"/>
      </geometry>
      <material name="black"/>
    </visual>
    <collision>
      <origin rpy="0 0 0" xyz="0 0 0"/>
      <geometry>
        <mesh filename="package://mh5_description/meshes/gripper.stl"/>
      </geometry>
    </collision>
    <inertial>
      <mass value="0.004"/>
      <inertia ixx="0.000000750" ixy="0.000000067" ixz="0.000000000" iyy="0.000001252" iyz="0.000000000" izz="0.000000794"/>
    </inertial>
  </link>
  <joint name="l_hip_r" type="revolute">
    <parent link="chest"/>
    <child link="left_hip_servo"/>
    <axis xyz="1.0 0 0"/>
    <origin rpy="0 0 0" xyz="0 0.032 0"/>
    <limit effort="1000.0" lower="-0.7853981633974483" upper="2.356194490192345" velocity="6.283185307179586"/>
    <dynamics damping="0.1" friction="0.0"/>
  </joint>
  <transmission name="l_hip_r_tran">
    <type>transmission_interface/SimpleTransmission</type>
    <joint name="l_hip_r">
      <hardwareInterface>hardware_interface/PositionJointInterface</hardwareInterface>
    </joint>
    <actuator name="l_hip_r_motor">
      <!-- <hardwareInterface>hardware_interface/PositionJointInterface</hardwareInterface> -->
      <mechanicalReduction>1</mechanicalReduction>
    </actuator>
  </transmission>
  <link name="left_hip_servo">
    <visual>
      <origin rpy="0 0 0" xyz="0 0 0"/>
      <geometry>
        <mesh filename="package://mh5_description/meshes/2XL430_2_idles_revC.stl"/>
      </geometry>
      <material name="black">
        <color rgba="0.2 0.2 0.2 1"/>
      </material>
    </visual>
    <collision>
      <origin rpy="0 0 0" xyz="0 0 0"/>
      <geometry>
        <mesh filename="package://mh5_description/meshes/2XL430_2_idles_revC.stl"/>
      </geometry>
    </collision>
    <inertial>
      <mass value="0.098"/>
      <inertia ixx="0.000026983" ixy="0.000000654" ixz="-0.000000002" iyy="0.000026983" iyz="0.000000001" izz="0.000019139"/>
    </inertial>
  </link>
  <joint name="l_hip_p" type="revolute">
    <parent link="left_hip_servo"/>
    <child link="left_thigh"/>
    <axis xyz="0 -1 0"/>
    <origin rpy="0 0 0" xyz="0 0 -0.024"/>
    <limit effort="1000.0" lower="-1.8849555921538759" upper="1.8849555921538759" velocity="6.283185307179586"/>
    <dynamics damping="0.1" friction="0.0"/>
  </joint>
  <transmission name="l_hip_p_tran">
    <type>transmission_interface/SimpleTransmission</type>
    <joint name="l_hip_p">
      <hardwareInterface>hardware_interface/PositionJointInterface</hardwareInterface>
    </joint>
    <actuator name="l_hip_p_motor">
      <!-- <hardwareInterface>hardware_interface/PositionJointInterface</hardwareInterface> -->
      <mechanicalReduction>1</mechanicalReduction>
    </actuator>
  </transmission>
  <link name="left_thigh">
    <visual>
      <origin rpy="0 0 0" xyz="0 0 0"/>
      <geometry>
        <mesh filename="package://mh5_description/meshes/thigh_revE.stl"/>
      </geometry>
      <material name="ivory">
        <color rgba="0.8 0.8 0.8 1"/>
      </material>
    </visual>
    <collision>
      <origin rpy="0 0 0" xyz="0 0 0"/>
      <geometry>
        <mesh filename="package://mh5_description/meshes/thigh_revE.stl"/>
      </geometry>
    </collision>
    <inertial>
      <mass value="0.016"/>
      <inertia ixx="0.000008595" ixy="0.000000000" ixz="-0.000000869" iyy="0.000005236" iyz="0.000000000" izz="0.000006459"/>
    </inertial>
  </link>
  <joint name="l_kne_p" type="revolute">
    <parent link="left_thigh"/>
    <child link="left_knee_servo"/>
    <axis xyz="0 1 0"/>
    <origin rpy="0 1.5707963267948966 0" xyz="-0.024 0 -0.061"/>
    <limit effort="1000.0" lower="0" upper="3.7699111843077517" velocity="6.283185307179586"/>
    <dynamics damping="0.1" friction="0.0"/>
  </joint>
  <transmission name="l_kne_p_tran">
    <type>transmission_interface/SimpleTransmission</type>
    <joint name="l_kne_p">
      <hardwareInterface>hardware_interface/PositionJointInterface</hardwareInterface>
    </joint>
    <actuator name="l_kne_p_motor">
      <!-- <hardwareInterface>hardware_interface/PositionJointInterface</hardwareInterface> -->
      <mechanicalReduction>1</mechanicalReduction>
    </actuator>
  </transmission>
  <link name="left_knee_servo">
    <visual>
      <origin rpy="0 0 0" xyz="0 0 0.024"/>
      <geometry>
        <mesh filename="package://mh5_description/meshes/2XL430_1_idle_revC.stl"/>
      </geometry>
      <material name="black">
        <color rgba="0.2 0.2 0.2 1"/>
      </material>
    </visual>
    <collision>
      <origin rpy="0 0 0" xyz="0 0 0.024"/>
      <geometry>
        <mesh filename="package://mh5_description/meshes/2XL430_1_idle_revC.stl"/>
      </geometry>
    </collision>
    <inertial>
      <mass value="0.098"/>
      <inertia ixx="0.000026983" ixy="0.000000654" ixz="-0.000000001" iyy="0.000026983" iyz="0.000000002" izz="0.000019139"/>
    </inertial>
  </link>
  <joint name="l_kne_y" type="revolute">
    <parent link="left_knee_servo"/>
    <child link="left_tibia"/>
    <axis xyz="0 0 1.0"/>
    <origin rpy="0 -1.5707963267948966 0" xyz="0.019 0 0.024"/>
    <limit effort="1000.0" lower="-0.7853981633974483" upper="0.7853981633974483" velocity="6.283185307179586"/>
    <dynamics damping="0.1" friction="0.0"/>
  </joint>
  <transmission name="l_kne_y_tran">
    <type>transmission_interface/SimpleTransmission</type>
    <joint name="l_kne_y">
      <hardwareInterface>hardware_interface/PositionJointInterface</hardwareInterface>
    </joint>
    <actuator name="l_kne_y_motor">
      <!-- <hardwareInterface>hardware_interface/PositionJointInterface</hardwareInterface> -->
      <mechanicalReduction>1</mechanicalReduction>
    </actuator>
  </transmission>
  <link name="left_tibia">
    <visual>
      <origin rpy="0 0 0" xyz="0 0 0"/>
      <geometry>
        <mesh filename="package://mh5_description/meshes/frame02_revC.stl"/>
      </geometry>
      <material name="ivory">
        <color rgba="0.8 0.8 0.8 1"/>
      </material>
    </visual>
    <collision>
      <origin rpy="0 0 0" xyz="0 0 0"/>
      <geometry>
        <mesh filename="package://mh5_description/meshes/frame02_revC.stl"/>
      </geometry>
    </collision>
    <inertial>
      <origin rpy="0 0 0" xyz="0 0 0"/>
      <mass value="0.0077"/>
      <inertia ixx="0.000003217" ixy="0.000000000" ixz="-0.000000011" iyy="0.000001377" iyz="0.000000000" izz="0.000002781"/>
    </inertial>
  </link>
  <joint name="l_ank_p" type="revolute">
    <parent link="left_tibia"/>
    <child link="left_ankle_servo"/>
    <axis xyz="1 0 0"/>
    <origin rpy="0 0 -1.5707963267948966" xyz="0 0 -0.034"/>
    <limit effort="1000.0" lower="-1.5707963267948966" upper="2.0106192982974678" velocity="6.283185307179586"/>
    <dynamics damping="0.1" friction="0.0"/>
  </joint>
  <transmission name="l_ank_p_tran">
    <type>transmission_interface/SimpleTransmission</type>
    <joint name="l_ank_p">
      <hardwareInterface>hardware_interface/PositionJointInterface</hardwareInterface>
    </joint>
    <actuator name="l_ank_p_motor">
      <!-- <hardwareInterface>hardware_interface/PositionJointInterface</hardwareInterface> -->
      <mechanicalReduction>1</mechanicalReduction>
    </actuator>
  </transmission>
  <link name="left_ankle_servo">
    <visual>
      <origin rpy="0 0 0" xyz="0 0 0"/>
      <geometry>
        <mesh filename="package://mh5_description/meshes/2XL430_2_idles_revC.stl"/>
      </geometry>
      <material name="black">
        <color rgba="0.2 0.2 0.2 1"/>
      </material>
    </visual>
    <collision>
      <origin rpy="0 0 0" xyz="0 0 0"/>
      <geometry>
        <mesh filename="package://mh5_description/meshes/2XL430_2_idles_revC.stl"/>
      </geometry>
    </collision>
    <inertial>
      <mass value="0.098"/>
      <inertia ixx="0.000026983" ixy="0.000000654" ixz="-0.000000002" iyy="0.000026983" iyz="0.000000001" izz="0.000019139"/>
    </inertial>
  </link>
  <joint name="l_ank_r" type="revolute">
    <parent link="left_ankle_servo"/>
    <child link="left_foot"/>
    <axis xyz="1.0 0 0"/>
    <origin rpy="0 0 1.5707963267948966" xyz="0 0 -0.024"/>
    <limit effort="1000.0" lower="-1.5707963267948966" upper="1.5707963267948966" velocity="6.283185307179586"/>
    <dynamics damping="0.1" friction="0.0"/>
  </joint>
  <transmission name="l_ank_r_tran">
    <type>transmission_interface/SimpleTransmission</type>
    <joint name="l_ank_r">
      <hardwareInterface>hardware_interface/PositionJointInterface</hardwareInterface>
    </joint>
    <actuator name="l_ank_r_motor">
      <!-- <hardwareInterface>hardware_interface/PositionJointInterface</hardwareInterface> -->
      <mechanicalReduction>1</mechanicalReduction>
    </actuator>
  </transmission>
  <link name="left_foot">
    <visual>
      <origin rpy="0 0 0" xyz="0 0 0"/>
      <geometry>
        <mesh filename="package://mh5_description/meshes/foot_revH.stl"/>
      </geometry>
      <material name="ivory">
        <color rgba="0.8 0.8 0.8 1"/>
      </material>
    </visual>
    <collision>
      <origin rpy="0 0 0" xyz="0 0 0"/>
      <geometry>
        <mesh filename="package://mh5_description/meshes/foot_revH.stl"/>
      </geometry>
    </collision>
    <inertial>
      <origin rpy="0 0 0" xyz="0 0 0"/>
      <mass value="0.038"/>
      <inertia ixx="0.000006451" ixy="0.000000000" ixz="0.000000341" iyy="0.000022262" iyz="0.000000000" izz="0.000026598"/>
    </inertial>
  </link>
  <!-- <joint name="${side}_battery_fixed" type="fixed">
            <parent link="${side}_foot"/>
            <child link="${side}_battery"/>
            <origin xyz="0.015 ${factor*0.009} -0.037" rpy="0 0 0"/>
        </joint> -->
  <!-- <link name="${side}_battery">
            <visual>
                <origin rpy="0 0 0" xyz="0 0 0"/>
                <geometry>
                    <mesh filename="package://mh5_description/meshes/battery_revC.stl"/>
                </geometry>
                <material name="blue">
                    <color rgba="0.2 0.2 1.0 1"/>
                </material>
            </visual>
            <collision>
                <origin rpy="0 0 0" xyz="0 0 0"/>
                <geometry>
                    <mesh filename="package://mh5_description/meshes/battery_revC.stl"/>
                </geometry>
            </collision>
            <inertial>
                <origin rpy="0 0 0" xyz="0 0 0"/>
                <mass value="0.155"/>
                <inertia
                    ixx="0.000034376"
                    iyy="0.000144254"
                    izz="0.000173658"
                    ixy="0.000000000"
                    ixz="0.000000000"
                    iyz="0.000000000" />
            </inertial>
        </link> -->
  <!-- <joint name="${side}_sole_fixed" type="fixed">
            <parent link="${side}_foot"/>
            <child link="${side}_landing"/>
            <origin xyz="0.0 0.0 -0.03825" rpy="0 0 0"/>
        </joint> -->
  <!-- <link name="${side}_landing" /> -->
  <joint name="r_hip_r" type="revolute">
    <parent link="chest"/>
    <child link="right_hip_servo"/>
    <axis xyz="-1.0 0 0"/>
    <origin rpy="0 0 0" xyz="0 -0.032 0"/>
    <limit effort="1000.0" lower="-0.7853981633974483" upper="2.356194490192345" velocity="6.283185307179586"/>
    <dynamics damping="0.1" friction="0.0"/>
  </joint>
  <transmission name="r_hip_r_tran">
    <type>transmission_interface/SimpleTransmission</type>
    <joint name="r_hip_r">
      <hardwareInterface>hardware_interface/PositionJointInterface</hardwareInterface>
    </joint>
    <actuator name="r_hip_r_motor">
      <!-- <hardwareInterface>hardware_interface/PositionJointInterface</hardwareInterface> -->
      <mechanicalReduction>1</mechanicalReduction>
    </actuator>
  </transmission>
  <link name="right_hip_servo">
    <visual>
      <origin rpy="0 0 0" xyz="0 0 0"/>
      <geometry>
        <mesh filename="package://mh5_description/meshes/2XL430_2_idles_revC.stl"/>
      </geometry>
      <material name="black">
        <color rgba="0.2 0.2 0.2 1"/>
      </material>
    </visual>
    <collision>
      <origin rpy="0 0 0" xyz="0 0 0"/>
      <geometry>
        <mesh filename="package://mh5_description/meshes/2XL430_2_idles_revC.stl"/>
      </geometry>
    </collision>
    <inertial>
      <mass value="0.098"/>
      <inertia ixx="0.000026983" ixy="0.000000654" ixz="-0.000000002" iyy="0.000026983" iyz="0.000000001" izz="0.000019139"/>
    </inertial>
  </link>
  <joint name="r_hip_p" type="revolute">
    <parent link="right_hip_servo"/>
    <child link="right_thigh"/>
    <axis xyz="0 -1 0"/>
    <origin rpy="0 0 0" xyz="0 0 -0.024"/>
    <limit effort="1000.0" lower="-1.8849555921538759" upper="1.8849555921538759" velocity="6.283185307179586"/>
    <dynamics damping="0.1" friction="0.0"/>
  </joint>
  <transmission name="r_hip_p_tran">
    <type>transmission_interface/SimpleTransmission</type>
    <joint name="r_hip_p">
      <hardwareInterface>hardware_interface/PositionJointInterface</hardwareInterface>
    </joint>
    <actuator name="r_hip_p_motor">
      <!-- <hardwareInterface>hardware_interface/PositionJointInterface</hardwareInterface> -->
      <mechanicalReduction>1</mechanicalReduction>
    </actuator>
  </transmission>
  <link name="right_thigh">
    <visual>
      <origin rpy="0 0 0" xyz="0 0 0"/>
      <geometry>
        <mesh filename="package://mh5_description/meshes/thigh_revE.stl"/>
      </geometry>
      <material name="ivory">
        <color rgba="0.8 0.8 0.8 1"/>
      </material>
    </visual>
    <collision>
      <origin rpy="0 0 0" xyz="0 0 0"/>
      <geometry>
        <mesh filename="package://mh5_description/meshes/thigh_revE.stl"/>
      </geometry>
    </collision>
    <inertial>
      <mass value="0.016"/>
      <inertia ixx="0.000008595" ixy="0.000000000" ixz="-0.000000869" iyy="0.000005236" iyz="0.000000000" izz="0.000006459"/>
    </inertial>
  </link>
  <joint name="r_kne_p" type="revolute">
    <parent link="right_thigh"/>
    <child link="right_knee_servo"/>
    <axis xyz="0 1 0"/>
    <origin rpy="0 1.5707963267948966 0" xyz="-0.024 0 -0.061"/>
    <limit effort="1000.0" lower="0" upper="3.7699111843077517" velocity="6.283185307179586"/>
    <dynamics damping="0.1" friction="0.0"/>
  </joint>
  <transmission name="r_kne_p_tran">
    <type>transmission_interface/SimpleTransmission</type>
    <joint name="r_kne_p">
      <hardwareInterface>hardware_interface/PositionJointInterface</hardwareInterface>
    </joint>
    <actuator name="r_kne_p_motor">
      <!-- <hardwareInterface>hardware_interface/PositionJointInterface</hardwareInterface> -->
      <mechanicalReduction>1</mechanicalReduction>
    </actuator>
  </transmission>
  <link name="right_knee_servo">
    <visual>
      <origin rpy="0 0 0" xyz="0 0 0.024"/>
      <geometry>
        <mesh filename="package://mh5_description/meshes/2XL430_1_idle_revC.stl"/>
      </geometry>
      <material name="black">
        <color rgba="0.2 0.2 0.2 1"/>
      </material>
    </visual>
    <collision>
      <origin rpy="0 0 0" xyz="0 0 0.024"/>
      <geometry>
        <mesh filename="package://mh5_description/meshes/2XL430_1_idle_revC.stl"/>
      </geometry>
    </collision>
    <inertial>
      <mass value="0.098"/>
      <inertia ixx="0.000026983" ixy="0.000000654" ixz="-0.000000001" iyy="0.000026983" iyz="0.000000002" izz="0.000019139"/>
    </inertial>
  </link>
  <joint name="r_kne_y" type="revolute">
    <parent link="right_knee_servo"/>
    <child link="right_tibia"/>
    <axis xyz="0 0 -1.0"/>
    <origin rpy="0 -1.5707963267948966 0" xyz="0.019 0 0.024"/>
    <limit effort="1000.0" lower="-0.7853981633974483" upper="0.7853981633974483" velocity="6.283185307179586"/>
    <dynamics damping="0.1" friction="0.0"/>
  </joint>
  <transmission name="r_kne_y_tran">
    <type>transmission_interface/SimpleTransmission</type>
    <joint name="r_kne_y">
      <hardwareInterface>hardware_interface/PositionJointInterface</hardwareInterface>
    </joint>
    <actuator name="r_kne_y_motor">
      <!-- <hardwareInterface>hardware_interface/PositionJointInterface</hardwareInterface> -->
      <mechanicalReduction>1</mechanicalReduction>
    </actuator>
  </transmission>
  <link name="right_tibia">
    <visual>
      <origin rpy="0 0 0" xyz="0 0 0"/>
      <geometry>
        <mesh filename="package://mh5_description/meshes/frame02_revC.stl"/>
      </geometry>
      <material name="ivory">
        <color rgba="0.8 0.8 0.8 1"/>
      </material>
    </visual>
    <collision>
      <origin rpy="0 0 0" xyz="0 0 0"/>
      <geometry>
        <mesh filename="package://mh5_description/meshes/frame02_revC.stl"/>
      </geometry>
    </collision>
    <inertial>
      <origin rpy="0 0 0" xyz="0 0 0"/>
      <mass value="0.0077"/>
      <inertia ixx="0.000003217" ixy="0.000000000" ixz="-0.000000011" iyy="0.000001377" iyz="0.000000000" izz="0.000002781"/>
    </inertial>
  </link>
  <joint name="r_ank_p" type="revolute">
    <parent link="right_tibia"/>
    <child link="right_ankle_servo"/>
    <axis xyz="1 0 0"/>
    <origin rpy="0 0 -1.5707963267948966" xyz="0 0 -0.034"/>
    <limit effort="1000.0" lower="-1.5707963267948966" upper="2.0106192982974678" velocity="6.283185307179586"/>
    <dynamics damping="0.1" friction="0.0"/>
  </joint>
  <transmission name="r_ank_p_tran">
    <type>transmission_interface/SimpleTransmission</type>
    <joint name="r_ank_p">
      <hardwareInterface>hardware_interface/PositionJointInterface</hardwareInterface>
    </joint>
    <actuator name="r_ank_p_motor">
      <!-- <hardwareInterface>hardware_interface/PositionJointInterface</hardwareInterface> -->
      <mechanicalReduction>1</mechanicalReduction>
    </actuator>
  </transmission>
  <link name="right_ankle_servo">
    <visual>
      <origin rpy="0 0 0" xyz="0 0 0"/>
      <geometry>
        <mesh filename="package://mh5_description/meshes/2XL430_2_idles_revC.stl"/>
      </geometry>
      <material name="black">
        <color rgba="0.2 0.2 0.2 1"/>
      </material>
    </visual>
    <collision>
      <origin rpy="0 0 0" xyz="0 0 0"/>
      <geometry>
        <mesh filename="package://mh5_description/meshes/2XL430_2_idles_revC.stl"/>
      </geometry>
    </collision>
    <inertial>
      <mass value="0.098"/>
      <inertia ixx="0.000026983" ixy="0.000000654" ixz="-0.000000002" iyy="0.000026983" iyz="0.000000001" izz="0.000019139"/>
    </inertial>
  </link>
  <joint name="r_ank_r" type="revolute">
    <parent link="right_ankle_servo"/>
    <child link="right_foot"/>
    <axis xyz="-1.0 0 0"/>
    <origin rpy="0 0 1.5707963267948966" xyz="0 0 -0.024"/>
    <limit effort="1000.0" lower="-1.5707963267948966" upper="1.5707963267948966" velocity="6.283185307179586"/>
    <dynamics damping="0.1" friction="0.0"/>
  </joint>
  <transmission name="r_ank_r_tran">
    <type>transmission_interface/SimpleTransmission</type>
    <joint name="r_ank_r">
      <hardwareInterface>hardware_interface/PositionJointInterface</hardwareInterface>
    </joint>
    <actuator name="r_ank_r_motor">
      <!-- <hardwareInterface>hardware_interface/PositionJointInterface</hardwareInterface> -->
      <mechanicalReduction>1</mechanicalReduction>
    </actuator>
  </transmission>
  <link name="right_foot">
    <visual>
      <origin rpy="0 0 0" xyz="0 0 0"/>
      <geometry>
        <mesh filename="package://mh5_description/meshes/foot_revH.stl"/>
      </geometry>
      <material name="ivory">
        <color rgba="0.8 0.8 0.8 1"/>
      </material>
    </visual>
    <collision>
      <origin rpy="0 0 0" xyz="0 0 0"/>
      <geometry>
        <mesh filename="package://mh5_description/meshes/foot_revH.stl"/>
      </geometry>
    </collision>
    <inertial>
      <origin rpy="0 0 0" xyz="0 0 0"/>
      <mass value="0.038"/>
      <inertia ixx="0.000006451" ixy="0.000000000" ixz="0.000000341" iyy="0.000022262" iyz="0.000000000" izz="0.000026598"/>
    </inertial>
  </link>
  <!-- <joint name="${side}_battery_fixed" type="fixed">
            <parent link="${side}_foot"/>
            <child link="${side}_battery"/>
            <origin xyz="0.015 ${factor*0.009} -0.037" rpy="0 0 0"/>
        </joint> -->
  <!-- <link name="${side}_battery">
            <visual>
                <origin rpy="0 0 0" xyz="0 0 0"/>
                <geometry>
                    <mesh filename="package://mh5_description/meshes/battery_revC.stl"/>
                </geometry>
                <material name="blue">
                    <color rgba="0.2 0.2 1.0 1"/>
                </material>
            </visual>
            <collision>
                <origin rpy="0 0 0" xyz="0 0 0"/>
                <geometry>
                    <mesh filename="package://mh5_description/meshes/battery_revC.stl"/>
                </geometry>
            </collision>
            <inertial>
                <origin rpy="0 0 0" xyz="0 0 0"/>
                <mass value="0.155"/>
                <inertia
                    ixx="0.000034376"
                    iyy="0.000144254"
                    izz="0.000173658"
                    ixy="0.000000000"
                    ixz="0.000000000"
                    iyz="0.000000000" />
            </inertial>
        </link> -->
  <!-- <joint name="${side}_sole_fixed" type="fixed">
            <parent link="${side}_foot"/>
            <child link="${side}_landing"/>
            <origin xyz="0.0 0.0 -0.03825" rpy="0 0 0"/>
        </joint> -->
  <!-- <link name="${side}_landing" /> -->
  <gazebo>
    <plugin filename="libgazebo_ros_control.so" name="gazebo_ros_control">
      <robotNamespace>/mh5_robot</robotNamespace>
    </plugin>
    <!-- <plugin name="joint_state_publisher" filename="libgazebo_ros_joint_state_publisher.so">
            <jointName>
                head_p, head_y,
                l_hip_p, l_hip_r, l_kne_p, l_kne_y, l_ank_p, l_ank_r,
                r_hip_p, r_hip_r, r_kne_p, r_kne_y, r_ank_p, r_ank_r
            </jointName>
            <updateRate>25</updateRate>
        </plugin> -->
  </gazebo>
</robot>
